[2022-02-25 08:43:27,645] {taskinstance.py:1037} INFO - Dependencies all met for <TaskInstance: test_s3_connection.upload_file_to_S3 scheduled__2022-02-25T00:00:00+00:00 [queued]>
[2022-02-25 08:43:27,656] {taskinstance.py:1037} INFO - Dependencies all met for <TaskInstance: test_s3_connection.upload_file_to_S3 scheduled__2022-02-25T00:00:00+00:00 [queued]>
[2022-02-25 08:43:27,657] {taskinstance.py:1243} INFO - 
--------------------------------------------------------------------------------
[2022-02-25 08:43:27,657] {taskinstance.py:1244} INFO - Starting attempt 5 of 5
[2022-02-25 08:43:27,658] {taskinstance.py:1245} INFO - 
--------------------------------------------------------------------------------
[2022-02-25 08:43:27,671] {taskinstance.py:1264} INFO - Executing <Task(PythonOperator): upload_file_to_S3> on 2022-02-25 00:00:00+00:00
[2022-02-25 08:43:27,677] {standard_task_runner.py:52} INFO - Started process 6291 to run task
[2022-02-25 08:43:27,682] {standard_task_runner.py:76} INFO - Running: ['***', 'tasks', 'run', 'test_s3_connection', 'upload_file_to_S3', 'scheduled__2022-02-25T00:00:00+00:00', '--job-id', '46', '--raw', '--subdir', 'DAGS_FOLDER/example_dag.py', '--cfg-path', '/tmp/tmp4dv0v9tk', '--error-file', '/tmp/tmpbfj123ol']
[2022-02-25 08:43:27,684] {standard_task_runner.py:77} INFO - Job 46: Subtask upload_file_to_S3
[2022-02-25 08:43:27,747] {logging_mixin.py:109} INFO - Running <TaskInstance: test_s3_connection.upload_file_to_S3 scheduled__2022-02-25T00:00:00+00:00 [running]> on host 267bf8a8032e
[2022-02-25 08:43:27,808] {taskinstance.py:1431} INFO - Exporting the following env vars:
AIRFLOW_CTX_DAG_OWNER=***
AIRFLOW_CTX_DAG_ID=test_s3_connection
AIRFLOW_CTX_TASK_ID=upload_file_to_S3
AIRFLOW_CTX_EXECUTION_DATE=2022-02-25T00:00:00+00:00
AIRFLOW_CTX_DAG_RUN_ID=scheduled__2022-02-25T00:00:00+00:00
[2022-02-25 08:43:30,062] {taskinstance.py:1718} ERROR - Task failed with exception
Traceback (most recent call last):
  File "/home/airflow/.local/lib/python3.7/site-packages/airflow/models/taskinstance.py", line 1334, in _run_raw_task
    self._execute_task_with_callbacks(context)
  File "/home/airflow/.local/lib/python3.7/site-packages/airflow/models/taskinstance.py", line 1460, in _execute_task_with_callbacks
    result = self._execute_task(context, self.task)
  File "/home/airflow/.local/lib/python3.7/site-packages/airflow/models/taskinstance.py", line 1516, in _execute_task
    result = execute_callable(context=context)
  File "/home/airflow/.local/lib/python3.7/site-packages/airflow/operators/python.py", line 174, in execute
    return_value = self.execute_callable()
  File "/home/airflow/.local/lib/python3.7/site-packages/airflow/operators/python.py", line 188, in execute_callable
    return self.python_callable(*self.op_args, **self.op_kwargs)
  File "/opt/airflow/dags/example_dag.py", line 11, in upload_file_to_s3
    s3.Bucket(bucket_name).upload_file(filename, key)
  File "/home/airflow/.local/lib/python3.7/site-packages/boto3/s3/inject.py", line 213, in bucket_upload_file
    ExtraArgs=ExtraArgs, Callback=Callback, Config=Config)
  File "/home/airflow/.local/lib/python3.7/site-packages/boto3/s3/inject.py", line 133, in upload_file
    extra_args=ExtraArgs, callback=Callback)
  File "/home/airflow/.local/lib/python3.7/site-packages/boto3/s3/transfer.py", line 287, in upload_file
    future.result()
  File "/home/airflow/.local/lib/python3.7/site-packages/s3transfer/futures.py", line 103, in result
    return self._coordinator.result()
  File "/home/airflow/.local/lib/python3.7/site-packages/s3transfer/futures.py", line 266, in result
    raise self._exception
  File "/home/airflow/.local/lib/python3.7/site-packages/s3transfer/tasks.py", line 139, in __call__
    return self._execute_main(kwargs)
  File "/home/airflow/.local/lib/python3.7/site-packages/s3transfer/tasks.py", line 162, in _execute_main
    return_value = self._main(**kwargs)
  File "/home/airflow/.local/lib/python3.7/site-packages/s3transfer/upload.py", line 757, in _main
    client.put_object(Bucket=bucket, Key=key, Body=body, **extra_args)
  File "/home/airflow/.local/lib/python3.7/site-packages/botocore/client.py", line 391, in _api_call
    return self._make_api_call(operation_name, kwargs)
  File "/home/airflow/.local/lib/python3.7/site-packages/botocore/client.py", line 706, in _make_api_call
    operation_model, request_dict, request_context)
  File "/home/airflow/.local/lib/python3.7/site-packages/botocore/client.py", line 725, in _make_request
    return self._endpoint.make_request(operation_model, request_dict)
  File "/home/airflow/.local/lib/python3.7/site-packages/botocore/endpoint.py", line 106, in make_request
    return self._send_request(request_dict, operation_model)
  File "/home/airflow/.local/lib/python3.7/site-packages/botocore/endpoint.py", line 179, in _send_request
    request = self.create_request(request_dict, operation_model)
  File "/home/airflow/.local/lib/python3.7/site-packages/botocore/endpoint.py", line 120, in create_request
    operation_name=operation_model.name)
  File "/home/airflow/.local/lib/python3.7/site-packages/botocore/hooks.py", line 357, in emit
    return self._emitter.emit(aliased_event_name, **kwargs)
  File "/home/airflow/.local/lib/python3.7/site-packages/botocore/hooks.py", line 228, in emit
    return self._emit(event_name, kwargs)
  File "/home/airflow/.local/lib/python3.7/site-packages/botocore/hooks.py", line 211, in _emit
    response = handler(**kwargs)
  File "/home/airflow/.local/lib/python3.7/site-packages/botocore/signers.py", line 93, in handler
    return self.sign(operation_name, request)
  File "/home/airflow/.local/lib/python3.7/site-packages/botocore/signers.py", line 165, in sign
    auth.add_auth(request)
  File "/home/airflow/.local/lib/python3.7/site-packages/botocore/auth.py", line 380, in add_auth
    raise NoCredentialsError()
botocore.exceptions.NoCredentialsError: Unable to locate credentials
[2022-02-25 08:43:30,093] {taskinstance.py:1282} INFO - Marking task as FAILED. dag_id=test_s3_connection, task_id=upload_file_to_S3, execution_date=20220225T000000, start_date=20220225T084327, end_date=20220225T084330
[2022-02-25 08:43:30,110] {standard_task_runner.py:92} ERROR - Failed to execute job 46 for task upload_file_to_S3
Traceback (most recent call last):
  File "/home/airflow/.local/lib/python3.7/site-packages/airflow/task/task_runner/standard_task_runner.py", line 85, in _start_by_fork
    args.func(args, dag=self.dag)
  File "/home/airflow/.local/lib/python3.7/site-packages/airflow/cli/cli_parser.py", line 48, in command
    return func(*args, **kwargs)
  File "/home/airflow/.local/lib/python3.7/site-packages/airflow/utils/cli.py", line 92, in wrapper
    return f(*args, **kwargs)
  File "/home/airflow/.local/lib/python3.7/site-packages/airflow/cli/commands/task_command.py", line 298, in task_run
    _run_task_by_selected_method(args, dag, ti)
  File "/home/airflow/.local/lib/python3.7/site-packages/airflow/cli/commands/task_command.py", line 107, in _run_task_by_selected_method
    _run_raw_task(args, ti)
  File "/home/airflow/.local/lib/python3.7/site-packages/airflow/cli/commands/task_command.py", line 184, in _run_raw_task
    error_file=args.error_file,
  File "/home/airflow/.local/lib/python3.7/site-packages/airflow/utils/session.py", line 70, in wrapper
    return func(*args, session=session, **kwargs)
  File "/home/airflow/.local/lib/python3.7/site-packages/airflow/models/taskinstance.py", line 1334, in _run_raw_task
    self._execute_task_with_callbacks(context)
  File "/home/airflow/.local/lib/python3.7/site-packages/airflow/models/taskinstance.py", line 1460, in _execute_task_with_callbacks
    result = self._execute_task(context, self.task)
  File "/home/airflow/.local/lib/python3.7/site-packages/airflow/models/taskinstance.py", line 1516, in _execute_task
    result = execute_callable(context=context)
  File "/home/airflow/.local/lib/python3.7/site-packages/airflow/operators/python.py", line 174, in execute
    return_value = self.execute_callable()
  File "/home/airflow/.local/lib/python3.7/site-packages/airflow/operators/python.py", line 188, in execute_callable
    return self.python_callable(*self.op_args, **self.op_kwargs)
  File "/opt/airflow/dags/example_dag.py", line 11, in upload_file_to_s3
    s3.Bucket(bucket_name).upload_file(filename, key)
  File "/home/airflow/.local/lib/python3.7/site-packages/boto3/s3/inject.py", line 213, in bucket_upload_file
    ExtraArgs=ExtraArgs, Callback=Callback, Config=Config)
  File "/home/airflow/.local/lib/python3.7/site-packages/boto3/s3/inject.py", line 133, in upload_file
    extra_args=ExtraArgs, callback=Callback)
  File "/home/airflow/.local/lib/python3.7/site-packages/boto3/s3/transfer.py", line 287, in upload_file
    future.result()
  File "/home/airflow/.local/lib/python3.7/site-packages/s3transfer/futures.py", line 103, in result
    return self._coordinator.result()
  File "/home/airflow/.local/lib/python3.7/site-packages/s3transfer/futures.py", line 266, in result
    raise self._exception
  File "/home/airflow/.local/lib/python3.7/site-packages/s3transfer/tasks.py", line 139, in __call__
    return self._execute_main(kwargs)
  File "/home/airflow/.local/lib/python3.7/site-packages/s3transfer/tasks.py", line 162, in _execute_main
    return_value = self._main(**kwargs)
  File "/home/airflow/.local/lib/python3.7/site-packages/s3transfer/upload.py", line 757, in _main
    client.put_object(Bucket=bucket, Key=key, Body=body, **extra_args)
  File "/home/airflow/.local/lib/python3.7/site-packages/botocore/client.py", line 391, in _api_call
    return self._make_api_call(operation_name, kwargs)
  File "/home/airflow/.local/lib/python3.7/site-packages/botocore/client.py", line 706, in _make_api_call
    operation_model, request_dict, request_context)
  File "/home/airflow/.local/lib/python3.7/site-packages/botocore/client.py", line 725, in _make_request
    return self._endpoint.make_request(operation_model, request_dict)
  File "/home/airflow/.local/lib/python3.7/site-packages/botocore/endpoint.py", line 106, in make_request
    return self._send_request(request_dict, operation_model)
  File "/home/airflow/.local/lib/python3.7/site-packages/botocore/endpoint.py", line 179, in _send_request
    request = self.create_request(request_dict, operation_model)
  File "/home/airflow/.local/lib/python3.7/site-packages/botocore/endpoint.py", line 120, in create_request
    operation_name=operation_model.name)
  File "/home/airflow/.local/lib/python3.7/site-packages/botocore/hooks.py", line 357, in emit
    return self._emitter.emit(aliased_event_name, **kwargs)
  File "/home/airflow/.local/lib/python3.7/site-packages/botocore/hooks.py", line 228, in emit
    return self._emit(event_name, kwargs)
  File "/home/airflow/.local/lib/python3.7/site-packages/botocore/hooks.py", line 211, in _emit
    response = handler(**kwargs)
  File "/home/airflow/.local/lib/python3.7/site-packages/botocore/signers.py", line 93, in handler
    return self.sign(operation_name, request)
  File "/home/airflow/.local/lib/python3.7/site-packages/botocore/signers.py", line 165, in sign
    auth.add_auth(request)
  File "/home/airflow/.local/lib/python3.7/site-packages/botocore/auth.py", line 380, in add_auth
    raise NoCredentialsError()
botocore.exceptions.NoCredentialsError: Unable to locate credentials
[2022-02-25 08:43:30,161] {local_task_job.py:154} INFO - Task exited with return code 1
[2022-02-25 08:43:30,201] {local_task_job.py:264} INFO - 0 downstream tasks scheduled from follow-on schedule check
