[2022-03-14 08:00:12,611] {taskinstance.py:1037} INFO - Dependencies all met for <TaskInstance: glue_poc.create_bucket scheduled__2022-03-13T00:00:00+00:00 [queued]>
[2022-03-14 08:00:12,636] {taskinstance.py:1037} INFO - Dependencies all met for <TaskInstance: glue_poc.create_bucket scheduled__2022-03-13T00:00:00+00:00 [queued]>
[2022-03-14 08:00:12,638] {taskinstance.py:1243} INFO - 
--------------------------------------------------------------------------------
[2022-03-14 08:00:12,639] {taskinstance.py:1244} INFO - Starting attempt 1 of 1
[2022-03-14 08:00:12,641] {taskinstance.py:1245} INFO - 
--------------------------------------------------------------------------------
[2022-03-14 08:00:12,662] {taskinstance.py:1264} INFO - Executing <Task(S3CreateBucketOperator): create_bucket> on 2022-03-13 00:00:00+00:00
[2022-03-14 08:00:12,694] {standard_task_runner.py:52} INFO - Started process 243 to run task
[2022-03-14 08:00:12,700] {standard_task_runner.py:76} INFO - Running: ['***', 'tasks', 'run', 'glue_poc', 'create_bucket', 'scheduled__2022-03-13T00:00:00+00:00', '--job-id', '114', '--raw', '--subdir', 'DAGS_FOLDER/glue_poc.py', '--cfg-path', '/tmp/tmp18bw7lia', '--error-file', '/tmp/tmp2jx_trgz']
[2022-03-14 08:00:12,714] {standard_task_runner.py:77} INFO - Job 114: Subtask create_bucket
[2022-03-14 08:00:12,831] {logging_mixin.py:109} INFO - Running <TaskInstance: glue_poc.create_bucket scheduled__2022-03-13T00:00:00+00:00 [running]> on host cdd2ec182991
[2022-03-14 08:00:12,962] {taskinstance.py:1431} INFO - Exporting the following env vars:
AIRFLOW_CTX_DAG_OWNER=***
AIRFLOW_CTX_DAG_ID=glue_poc
AIRFLOW_CTX_TASK_ID=create_bucket
AIRFLOW_CTX_EXECUTION_DATE=2022-03-13T00:00:00+00:00
AIRFLOW_CTX_DAG_RUN_ID=scheduled__2022-03-13T00:00:00+00:00
[2022-03-14 08:00:12,983] {base_aws.py:431} WARNING - Unable to use Airflow Connection for credentials.
[2022-03-14 08:00:15,627] {taskinstance.py:1718} ERROR - Task failed with exception
Traceback (most recent call last):
  File "/home/airflow/.local/lib/python3.7/site-packages/airflow/models/taskinstance.py", line 1334, in _run_raw_task
    self._execute_task_with_callbacks(context)
  File "/home/airflow/.local/lib/python3.7/site-packages/airflow/models/taskinstance.py", line 1460, in _execute_task_with_callbacks
    result = self._execute_task(context, self.task)
  File "/home/airflow/.local/lib/python3.7/site-packages/airflow/models/taskinstance.py", line 1516, in _execute_task
    result = execute_callable(context=context)
  File "/home/airflow/.local/lib/python3.7/site-packages/airflow/providers/amazon/aws/operators/s3.py", line 72, in execute
    if not s3_hook.check_for_bucket(self.bucket_name):
  File "/home/airflow/.local/lib/python3.7/site-packages/airflow/providers/amazon/aws/hooks/s3.py", line 62, in wrapper
    return func(*bound_args.args, **bound_args.kwargs)
  File "/home/airflow/.local/lib/python3.7/site-packages/airflow/providers/amazon/aws/hooks/s3.py", line 159, in check_for_bucket
    self.get_conn().head_bucket(Bucket=bucket_name)
  File "/home/airflow/.local/lib/python3.7/site-packages/botocore/client.py", line 391, in _api_call
    return self._make_api_call(operation_name, kwargs)
  File "/home/airflow/.local/lib/python3.7/site-packages/botocore/client.py", line 706, in _make_api_call
    operation_model, request_dict, request_context)
  File "/home/airflow/.local/lib/python3.7/site-packages/botocore/client.py", line 725, in _make_request
    return self._endpoint.make_request(operation_model, request_dict)
  File "/home/airflow/.local/lib/python3.7/site-packages/botocore/endpoint.py", line 106, in make_request
    return self._send_request(request_dict, operation_model)
  File "/home/airflow/.local/lib/python3.7/site-packages/botocore/endpoint.py", line 179, in _send_request
    request = self.create_request(request_dict, operation_model)
  File "/home/airflow/.local/lib/python3.7/site-packages/botocore/endpoint.py", line 120, in create_request
    operation_name=operation_model.name)
  File "/home/airflow/.local/lib/python3.7/site-packages/botocore/hooks.py", line 357, in emit
    return self._emitter.emit(aliased_event_name, **kwargs)
  File "/home/airflow/.local/lib/python3.7/site-packages/botocore/hooks.py", line 228, in emit
    return self._emit(event_name, kwargs)
  File "/home/airflow/.local/lib/python3.7/site-packages/botocore/hooks.py", line 211, in _emit
    response = handler(**kwargs)
  File "/home/airflow/.local/lib/python3.7/site-packages/botocore/signers.py", line 93, in handler
    return self.sign(operation_name, request)
  File "/home/airflow/.local/lib/python3.7/site-packages/botocore/signers.py", line 165, in sign
    auth.add_auth(request)
  File "/home/airflow/.local/lib/python3.7/site-packages/botocore/auth.py", line 380, in add_auth
    raise NoCredentialsError()
botocore.exceptions.NoCredentialsError: Unable to locate credentials
[2022-03-14 08:00:15,661] {taskinstance.py:1282} INFO - Marking task as FAILED. dag_id=glue_poc, task_id=create_bucket, execution_date=20220313T000000, start_date=20220314T080012, end_date=20220314T080015
[2022-03-14 08:00:16,029] {standard_task_runner.py:92} ERROR - Failed to execute job 114 for task create_bucket
Traceback (most recent call last):
  File "/home/airflow/.local/lib/python3.7/site-packages/airflow/task/task_runner/standard_task_runner.py", line 85, in _start_by_fork
    args.func(args, dag=self.dag)
  File "/home/airflow/.local/lib/python3.7/site-packages/airflow/cli/cli_parser.py", line 48, in command
    return func(*args, **kwargs)
  File "/home/airflow/.local/lib/python3.7/site-packages/airflow/utils/cli.py", line 92, in wrapper
    return f(*args, **kwargs)
  File "/home/airflow/.local/lib/python3.7/site-packages/airflow/cli/commands/task_command.py", line 298, in task_run
    _run_task_by_selected_method(args, dag, ti)
  File "/home/airflow/.local/lib/python3.7/site-packages/airflow/cli/commands/task_command.py", line 107, in _run_task_by_selected_method
    _run_raw_task(args, ti)
  File "/home/airflow/.local/lib/python3.7/site-packages/airflow/cli/commands/task_command.py", line 184, in _run_raw_task
    error_file=args.error_file,
  File "/home/airflow/.local/lib/python3.7/site-packages/airflow/utils/session.py", line 70, in wrapper
    return func(*args, session=session, **kwargs)
  File "/home/airflow/.local/lib/python3.7/site-packages/airflow/models/taskinstance.py", line 1334, in _run_raw_task
    self._execute_task_with_callbacks(context)
  File "/home/airflow/.local/lib/python3.7/site-packages/airflow/models/taskinstance.py", line 1460, in _execute_task_with_callbacks
    result = self._execute_task(context, self.task)
  File "/home/airflow/.local/lib/python3.7/site-packages/airflow/models/taskinstance.py", line 1516, in _execute_task
    result = execute_callable(context=context)
  File "/home/airflow/.local/lib/python3.7/site-packages/airflow/providers/amazon/aws/operators/s3.py", line 72, in execute
    if not s3_hook.check_for_bucket(self.bucket_name):
  File "/home/airflow/.local/lib/python3.7/site-packages/airflow/providers/amazon/aws/hooks/s3.py", line 62, in wrapper
    return func(*bound_args.args, **bound_args.kwargs)
  File "/home/airflow/.local/lib/python3.7/site-packages/airflow/providers/amazon/aws/hooks/s3.py", line 159, in check_for_bucket
    self.get_conn().head_bucket(Bucket=bucket_name)
  File "/home/airflow/.local/lib/python3.7/site-packages/botocore/client.py", line 391, in _api_call
    return self._make_api_call(operation_name, kwargs)
  File "/home/airflow/.local/lib/python3.7/site-packages/botocore/client.py", line 706, in _make_api_call
    operation_model, request_dict, request_context)
  File "/home/airflow/.local/lib/python3.7/site-packages/botocore/client.py", line 725, in _make_request
    return self._endpoint.make_request(operation_model, request_dict)
  File "/home/airflow/.local/lib/python3.7/site-packages/botocore/endpoint.py", line 106, in make_request
    return self._send_request(request_dict, operation_model)
  File "/home/airflow/.local/lib/python3.7/site-packages/botocore/endpoint.py", line 179, in _send_request
    request = self.create_request(request_dict, operation_model)
  File "/home/airflow/.local/lib/python3.7/site-packages/botocore/endpoint.py", line 120, in create_request
    operation_name=operation_model.name)
  File "/home/airflow/.local/lib/python3.7/site-packages/botocore/hooks.py", line 357, in emit
    return self._emitter.emit(aliased_event_name, **kwargs)
  File "/home/airflow/.local/lib/python3.7/site-packages/botocore/hooks.py", line 228, in emit
    return self._emit(event_name, kwargs)
  File "/home/airflow/.local/lib/python3.7/site-packages/botocore/hooks.py", line 211, in _emit
    response = handler(**kwargs)
  File "/home/airflow/.local/lib/python3.7/site-packages/botocore/signers.py", line 93, in handler
    return self.sign(operation_name, request)
  File "/home/airflow/.local/lib/python3.7/site-packages/botocore/signers.py", line 165, in sign
    auth.add_auth(request)
  File "/home/airflow/.local/lib/python3.7/site-packages/botocore/auth.py", line 380, in add_auth
    raise NoCredentialsError()
botocore.exceptions.NoCredentialsError: Unable to locate credentials
[2022-03-14 08:00:16,095] {local_task_job.py:154} INFO - Task exited with return code 1
[2022-03-14 08:00:16,154] {local_task_job.py:264} INFO - 0 downstream tasks scheduled from follow-on schedule check
