[2022-03-15 08:38:23,073] {taskinstance.py:1037} INFO - Dependencies all met for <TaskInstance: glue_poc.create_bucket scheduled__2022-03-13T00:00:00+00:00 [queued]>
[2022-03-15 08:38:23,098] {taskinstance.py:1037} INFO - Dependencies all met for <TaskInstance: glue_poc.create_bucket scheduled__2022-03-13T00:00:00+00:00 [queued]>
[2022-03-15 08:38:23,100] {taskinstance.py:1243} INFO - 
--------------------------------------------------------------------------------
[2022-03-15 08:38:23,103] {taskinstance.py:1244} INFO - Starting attempt 19 of 19
[2022-03-15 08:38:23,104] {taskinstance.py:1245} INFO - 
--------------------------------------------------------------------------------
[2022-03-15 08:38:23,126] {taskinstance.py:1264} INFO - Executing <Task(PythonOperator): create_bucket> on 2022-03-13 00:00:00+00:00
[2022-03-15 08:38:23,138] {standard_task_runner.py:52} INFO - Started process 244 to run task
[2022-03-15 08:38:23,144] {standard_task_runner.py:76} INFO - Running: ['***', 'tasks', 'run', 'glue_poc', 'create_bucket', 'scheduled__2022-03-13T00:00:00+00:00', '--job-id', '266', '--raw', '--subdir', 'DAGS_FOLDER/glue_poc.py', '--cfg-path', '/tmp/tmpcz4qe3g9', '--error-file', '/tmp/tmpdzethyhg']
[2022-03-15 08:38:23,146] {standard_task_runner.py:77} INFO - Job 266: Subtask create_bucket
[2022-03-15 08:38:23,242] {logging_mixin.py:109} INFO - Running <TaskInstance: glue_poc.create_bucket scheduled__2022-03-13T00:00:00+00:00 [running]> on host 26f80f9099ae
[2022-03-15 08:38:23,366] {taskinstance.py:1431} INFO - Exporting the following env vars:
AIRFLOW_CTX_DAG_OWNER=***
AIRFLOW_CTX_DAG_ID=glue_poc
AIRFLOW_CTX_TASK_ID=create_bucket
AIRFLOW_CTX_EXECUTION_DATE=2022-03-13T00:00:00+00:00
AIRFLOW_CTX_DAG_RUN_ID=scheduled__2022-03-13T00:00:00+00:00
[2022-03-15 08:38:23,392] {base_aws.py:194} INFO - Credentials retrieved from extra_config
[2022-03-15 08:38:25,354] {taskinstance.py:1718} ERROR - Task failed with exception
Traceback (most recent call last):
  File "/home/airflow/.local/lib/python3.7/site-packages/airflow/models/taskinstance.py", line 1334, in _run_raw_task
    self._execute_task_with_callbacks(context)
  File "/home/airflow/.local/lib/python3.7/site-packages/airflow/models/taskinstance.py", line 1460, in _execute_task_with_callbacks
    result = self._execute_task(context, self.task)
  File "/home/airflow/.local/lib/python3.7/site-packages/airflow/models/taskinstance.py", line 1516, in _execute_task
    result = execute_callable(context=context)
  File "/home/airflow/.local/lib/python3.7/site-packages/airflow/operators/python.py", line 174, in execute
    return_value = self.execute_callable()
  File "/home/airflow/.local/lib/python3.7/site-packages/airflow/operators/python.py", line 188, in execute_callable
    return self.python_callable(*self.op_args, **self.op_kwargs)
  File "/opt/airflow/dags/glue_poc.py", line 24, in create_bucket
    S3_HOOK.create_bucket(bucket_name=bucket_name, region_name="ap-south-1")
  File "/home/airflow/.local/lib/python3.7/site-packages/airflow/providers/amazon/aws/hooks/s3.py", line 62, in wrapper
    return func(*bound_args.args, **bound_args.kwargs)
  File "/home/airflow/.local/lib/python3.7/site-packages/airflow/providers/amazon/aws/hooks/s3.py", line 199, in create_bucket
    Bucket=bucket_name, CreateBucketConfiguration={'LocationConstraint': region_name}
  File "/home/airflow/.local/lib/python3.7/site-packages/botocore/client.py", line 391, in _api_call
    return self._make_api_call(operation_name, kwargs)
  File "/home/airflow/.local/lib/python3.7/site-packages/botocore/client.py", line 719, in _make_api_call
    raise error_class(parsed_response, operation_name)
botocore.exceptions.ClientError: An error occurred (OperationAborted) when calling the CreateBucket operation: A conflicting conditional operation is currently in progress against this resource. Please try again.
[2022-03-15 08:38:25,381] {taskinstance.py:1282} INFO - Marking task as FAILED. dag_id=glue_poc, task_id=create_bucket, execution_date=20220313T000000, start_date=20220315T083823, end_date=20220315T083825
[2022-03-15 08:38:25,409] {standard_task_runner.py:92} ERROR - Failed to execute job 266 for task create_bucket
Traceback (most recent call last):
  File "/home/airflow/.local/lib/python3.7/site-packages/airflow/task/task_runner/standard_task_runner.py", line 85, in _start_by_fork
    args.func(args, dag=self.dag)
  File "/home/airflow/.local/lib/python3.7/site-packages/airflow/cli/cli_parser.py", line 48, in command
    return func(*args, **kwargs)
  File "/home/airflow/.local/lib/python3.7/site-packages/airflow/utils/cli.py", line 92, in wrapper
    return f(*args, **kwargs)
  File "/home/airflow/.local/lib/python3.7/site-packages/airflow/cli/commands/task_command.py", line 298, in task_run
    _run_task_by_selected_method(args, dag, ti)
  File "/home/airflow/.local/lib/python3.7/site-packages/airflow/cli/commands/task_command.py", line 107, in _run_task_by_selected_method
    _run_raw_task(args, ti)
  File "/home/airflow/.local/lib/python3.7/site-packages/airflow/cli/commands/task_command.py", line 184, in _run_raw_task
    error_file=args.error_file,
  File "/home/airflow/.local/lib/python3.7/site-packages/airflow/utils/session.py", line 70, in wrapper
    return func(*args, session=session, **kwargs)
  File "/home/airflow/.local/lib/python3.7/site-packages/airflow/models/taskinstance.py", line 1334, in _run_raw_task
    self._execute_task_with_callbacks(context)
  File "/home/airflow/.local/lib/python3.7/site-packages/airflow/models/taskinstance.py", line 1460, in _execute_task_with_callbacks
    result = self._execute_task(context, self.task)
  File "/home/airflow/.local/lib/python3.7/site-packages/airflow/models/taskinstance.py", line 1516, in _execute_task
    result = execute_callable(context=context)
  File "/home/airflow/.local/lib/python3.7/site-packages/airflow/operators/python.py", line 174, in execute
    return_value = self.execute_callable()
  File "/home/airflow/.local/lib/python3.7/site-packages/airflow/operators/python.py", line 188, in execute_callable
    return self.python_callable(*self.op_args, **self.op_kwargs)
  File "/opt/airflow/dags/glue_poc.py", line 24, in create_bucket
    S3_HOOK.create_bucket(bucket_name=bucket_name, region_name="ap-south-1")
  File "/home/airflow/.local/lib/python3.7/site-packages/airflow/providers/amazon/aws/hooks/s3.py", line 62, in wrapper
    return func(*bound_args.args, **bound_args.kwargs)
  File "/home/airflow/.local/lib/python3.7/site-packages/airflow/providers/amazon/aws/hooks/s3.py", line 199, in create_bucket
    Bucket=bucket_name, CreateBucketConfiguration={'LocationConstraint': region_name}
  File "/home/airflow/.local/lib/python3.7/site-packages/botocore/client.py", line 391, in _api_call
    return self._make_api_call(operation_name, kwargs)
  File "/home/airflow/.local/lib/python3.7/site-packages/botocore/client.py", line 719, in _make_api_call
    raise error_class(parsed_response, operation_name)
botocore.exceptions.ClientError: An error occurred (OperationAborted) when calling the CreateBucket operation: A conflicting conditional operation is currently in progress against this resource. Please try again.
[2022-03-15 08:38:25,467] {local_task_job.py:154} INFO - Task exited with return code 1
[2022-03-15 08:38:25,528] {local_task_job.py:264} INFO - 0 downstream tasks scheduled from follow-on schedule check
