[2022-02-28 07:22:10,751] {taskinstance.py:1037} INFO - Dependencies all met for <TaskInstance: test_s3_connection.create_bucket scheduled__2022-02-25T00:00:00+00:00 [queued]>
[2022-02-28 07:22:10,772] {taskinstance.py:1037} INFO - Dependencies all met for <TaskInstance: test_s3_connection.create_bucket scheduled__2022-02-25T00:00:00+00:00 [queued]>
[2022-02-28 07:22:10,774] {taskinstance.py:1243} INFO - 
--------------------------------------------------------------------------------
[2022-02-28 07:22:10,776] {taskinstance.py:1244} INFO - Starting attempt 2 of 2
[2022-02-28 07:22:10,777] {taskinstance.py:1245} INFO - 
--------------------------------------------------------------------------------
[2022-02-28 07:22:10,798] {taskinstance.py:1264} INFO - Executing <Task(S3CreateBucketOperator): create_bucket> on 2022-02-25 00:00:00+00:00
[2022-02-28 07:22:10,806] {standard_task_runner.py:52} INFO - Started process 14369 to run task
[2022-02-28 07:22:10,812] {standard_task_runner.py:76} INFO - Running: ['***', 'tasks', 'run', 'test_s3_connection', 'create_bucket', 'scheduled__2022-02-25T00:00:00+00:00', '--job-id', '56', '--raw', '--subdir', 'DAGS_FOLDER/example_dag.py', '--cfg-path', '/tmp/tmpendhuuvl', '--error-file', '/tmp/tmpss2mixyr']
[2022-02-28 07:22:10,815] {standard_task_runner.py:77} INFO - Job 56: Subtask create_bucket
[2022-02-28 07:22:10,920] {logging_mixin.py:109} INFO - Running <TaskInstance: test_s3_connection.create_bucket scheduled__2022-02-25T00:00:00+00:00 [running]> on host cdd2ec182991
[2022-02-28 07:22:10,999] {taskinstance.py:1431} INFO - Exporting the following env vars:
AIRFLOW_CTX_DAG_OWNER=***
AIRFLOW_CTX_DAG_ID=test_s3_connection
AIRFLOW_CTX_TASK_ID=create_bucket
AIRFLOW_CTX_EXECUTION_DATE=2022-02-25T00:00:00+00:00
AIRFLOW_CTX_DAG_RUN_ID=scheduled__2022-02-25T00:00:00+00:00
[2022-02-28 07:22:11,014] {base_aws.py:194} INFO - Credentials retrieved from extra_config
[2022-02-28 07:22:12,944] {s3.py:162} ERROR - Not Found
[2022-02-28 07:22:13,381] {taskinstance.py:1718} ERROR - Task failed with exception
Traceback (most recent call last):
  File "/home/airflow/.local/lib/python3.7/site-packages/airflow/models/taskinstance.py", line 1334, in _run_raw_task
    self._execute_task_with_callbacks(context)
  File "/home/airflow/.local/lib/python3.7/site-packages/airflow/models/taskinstance.py", line 1460, in _execute_task_with_callbacks
    result = self._execute_task(context, self.task)
  File "/home/airflow/.local/lib/python3.7/site-packages/airflow/models/taskinstance.py", line 1516, in _execute_task
    result = execute_callable(context=context)
  File "/home/airflow/.local/lib/python3.7/site-packages/airflow/providers/amazon/aws/operators/s3.py", line 73, in execute
    s3_hook.create_bucket(bucket_name=self.bucket_name, region_name=self.region_name)
  File "/home/airflow/.local/lib/python3.7/site-packages/airflow/providers/amazon/aws/hooks/s3.py", line 62, in wrapper
    return func(*bound_args.args, **bound_args.kwargs)
  File "/home/airflow/.local/lib/python3.7/site-packages/airflow/providers/amazon/aws/hooks/s3.py", line 196, in create_bucket
    self.get_conn().create_bucket(Bucket=bucket_name)
  File "/home/airflow/.local/lib/python3.7/site-packages/botocore/client.py", line 391, in _api_call
    return self._make_api_call(operation_name, kwargs)
  File "/home/airflow/.local/lib/python3.7/site-packages/botocore/client.py", line 719, in _make_api_call
    raise error_class(parsed_response, operation_name)
botocore.exceptions.ClientError: An error occurred (InvalidBucketName) when calling the CreateBucket operation: The specified bucket is not valid.
[2022-02-28 07:22:13,402] {taskinstance.py:1282} INFO - Marking task as FAILED. dag_id=test_s3_connection, task_id=create_bucket, execution_date=20220225T000000, start_date=20220228T072210, end_date=20220228T072213
[2022-02-28 07:22:13,423] {standard_task_runner.py:92} ERROR - Failed to execute job 56 for task create_bucket
Traceback (most recent call last):
  File "/home/airflow/.local/lib/python3.7/site-packages/airflow/task/task_runner/standard_task_runner.py", line 85, in _start_by_fork
    args.func(args, dag=self.dag)
  File "/home/airflow/.local/lib/python3.7/site-packages/airflow/cli/cli_parser.py", line 48, in command
    return func(*args, **kwargs)
  File "/home/airflow/.local/lib/python3.7/site-packages/airflow/utils/cli.py", line 92, in wrapper
    return f(*args, **kwargs)
  File "/home/airflow/.local/lib/python3.7/site-packages/airflow/cli/commands/task_command.py", line 298, in task_run
    _run_task_by_selected_method(args, dag, ti)
  File "/home/airflow/.local/lib/python3.7/site-packages/airflow/cli/commands/task_command.py", line 107, in _run_task_by_selected_method
    _run_raw_task(args, ti)
  File "/home/airflow/.local/lib/python3.7/site-packages/airflow/cli/commands/task_command.py", line 184, in _run_raw_task
    error_file=args.error_file,
  File "/home/airflow/.local/lib/python3.7/site-packages/airflow/utils/session.py", line 70, in wrapper
    return func(*args, session=session, **kwargs)
  File "/home/airflow/.local/lib/python3.7/site-packages/airflow/models/taskinstance.py", line 1334, in _run_raw_task
    self._execute_task_with_callbacks(context)
  File "/home/airflow/.local/lib/python3.7/site-packages/airflow/models/taskinstance.py", line 1460, in _execute_task_with_callbacks
    result = self._execute_task(context, self.task)
  File "/home/airflow/.local/lib/python3.7/site-packages/airflow/models/taskinstance.py", line 1516, in _execute_task
    result = execute_callable(context=context)
  File "/home/airflow/.local/lib/python3.7/site-packages/airflow/providers/amazon/aws/operators/s3.py", line 73, in execute
    s3_hook.create_bucket(bucket_name=self.bucket_name, region_name=self.region_name)
  File "/home/airflow/.local/lib/python3.7/site-packages/airflow/providers/amazon/aws/hooks/s3.py", line 62, in wrapper
    return func(*bound_args.args, **bound_args.kwargs)
  File "/home/airflow/.local/lib/python3.7/site-packages/airflow/providers/amazon/aws/hooks/s3.py", line 196, in create_bucket
    self.get_conn().create_bucket(Bucket=bucket_name)
  File "/home/airflow/.local/lib/python3.7/site-packages/botocore/client.py", line 391, in _api_call
    return self._make_api_call(operation_name, kwargs)
  File "/home/airflow/.local/lib/python3.7/site-packages/botocore/client.py", line 719, in _make_api_call
    raise error_class(parsed_response, operation_name)
botocore.exceptions.ClientError: An error occurred (InvalidBucketName) when calling the CreateBucket operation: The specified bucket is not valid.
[2022-02-28 07:22:13,445] {local_task_job.py:154} INFO - Task exited with return code 1
[2022-02-28 07:22:13,504] {local_task_job.py:264} INFO - 0 downstream tasks scheduled from follow-on schedule check
