[2022-02-28 07:23:43,660] {taskinstance.py:1037} INFO - Dependencies all met for <TaskInstance: test_s3_connection.read_file_from_s3 scheduled__2022-02-25T00:00:00+00:00 [queued]>
[2022-02-28 07:23:43,684] {taskinstance.py:1037} INFO - Dependencies all met for <TaskInstance: test_s3_connection.read_file_from_s3 scheduled__2022-02-25T00:00:00+00:00 [queued]>
[2022-02-28 07:23:43,685] {taskinstance.py:1243} INFO - 
--------------------------------------------------------------------------------
[2022-02-28 07:23:43,686] {taskinstance.py:1244} INFO - Starting attempt 2 of 2
[2022-02-28 07:23:43,687] {taskinstance.py:1245} INFO - 
--------------------------------------------------------------------------------
[2022-02-28 07:23:43,702] {taskinstance.py:1264} INFO - Executing <Task(PythonOperator): read_file_from_s3> on 2022-02-25 00:00:00+00:00
[2022-02-28 07:23:43,707] {standard_task_runner.py:52} INFO - Started process 14462 to run task
[2022-02-28 07:23:43,712] {standard_task_runner.py:76} INFO - Running: ['***', 'tasks', 'run', 'test_s3_connection', 'read_file_from_s3', 'scheduled__2022-02-25T00:00:00+00:00', '--job-id', '59', '--raw', '--subdir', 'DAGS_FOLDER/example_dag.py', '--cfg-path', '/tmp/tmp6osighd8', '--error-file', '/tmp/tmpynopa_9_']
[2022-02-28 07:23:43,714] {standard_task_runner.py:77} INFO - Job 59: Subtask read_file_from_s3
[2022-02-28 07:23:43,774] {logging_mixin.py:109} INFO - Running <TaskInstance: test_s3_connection.read_file_from_s3 scheduled__2022-02-25T00:00:00+00:00 [running]> on host cdd2ec182991
[2022-02-28 07:23:43,834] {taskinstance.py:1431} INFO - Exporting the following env vars:
AIRFLOW_CTX_DAG_OWNER=***
AIRFLOW_CTX_DAG_ID=test_s3_connection
AIRFLOW_CTX_TASK_ID=read_file_from_s3
AIRFLOW_CTX_EXECUTION_DATE=2022-02-25T00:00:00+00:00
AIRFLOW_CTX_DAG_RUN_ID=scheduled__2022-02-25T00:00:00+00:00
[2022-02-28 07:23:43,846] {base_aws.py:194} INFO - Credentials retrieved from extra_config
[2022-02-28 07:23:44,795] {taskinstance.py:1718} ERROR - Task failed with exception
Traceback (most recent call last):
  File "/home/airflow/.local/lib/python3.7/site-packages/airflow/models/taskinstance.py", line 1334, in _run_raw_task
    self._execute_task_with_callbacks(context)
  File "/home/airflow/.local/lib/python3.7/site-packages/airflow/models/taskinstance.py", line 1460, in _execute_task_with_callbacks
    result = self._execute_task(context, self.task)
  File "/home/airflow/.local/lib/python3.7/site-packages/airflow/models/taskinstance.py", line 1516, in _execute_task
    result = execute_callable(context=context)
  File "/home/airflow/.local/lib/python3.7/site-packages/airflow/operators/python.py", line 174, in execute
    return_value = self.execute_callable()
  File "/home/airflow/.local/lib/python3.7/site-packages/airflow/operators/python.py", line 188, in execute_callable
    return self.python_callable(*self.op_args, **self.op_kwargs)
  File "/opt/airflow/dags/example_dag.py", line 17, in read_file_from_s3
    print(s3_hook.read_key(key, bucket_name))
  File "/home/airflow/.local/lib/python3.7/site-packages/airflow/providers/amazon/aws/hooks/s3.py", line 62, in wrapper
    return func(*bound_args.args, **bound_args.kwargs)
  File "/home/airflow/.local/lib/python3.7/site-packages/airflow/providers/amazon/aws/hooks/s3.py", line 90, in wrapper
    return func(*bound_args.args, **bound_args.kwargs)
  File "/home/airflow/.local/lib/python3.7/site-packages/airflow/providers/amazon/aws/hooks/s3.py", line 354, in read_key
    obj = self.get_key(key, bucket_name)
  File "/home/airflow/.local/lib/python3.7/site-packages/airflow/providers/amazon/aws/hooks/s3.py", line 62, in wrapper
    return func(*bound_args.args, **bound_args.kwargs)
  File "/home/airflow/.local/lib/python3.7/site-packages/airflow/providers/amazon/aws/hooks/s3.py", line 90, in wrapper
    return func(*bound_args.args, **bound_args.kwargs)
  File "/home/airflow/.local/lib/python3.7/site-packages/airflow/providers/amazon/aws/hooks/s3.py", line 340, in get_key
    obj.load()
  File "/home/airflow/.local/lib/python3.7/site-packages/boto3/resources/factory.py", line 505, in do_action
    response = action(self, *args, **kwargs)
  File "/home/airflow/.local/lib/python3.7/site-packages/boto3/resources/action.py", line 83, in __call__
    response = getattr(parent.meta.client, operation_name)(*args, **params)
  File "/home/airflow/.local/lib/python3.7/site-packages/botocore/client.py", line 391, in _api_call
    return self._make_api_call(operation_name, kwargs)
  File "/home/airflow/.local/lib/python3.7/site-packages/botocore/client.py", line 719, in _make_api_call
    raise error_class(parsed_response, operation_name)
botocore.exceptions.ClientError: An error occurred (404) when calling the HeadObject operation: Not Found
[2022-02-28 07:23:44,823] {taskinstance.py:1282} INFO - Marking task as FAILED. dag_id=test_s3_connection, task_id=read_file_from_s3, execution_date=20220225T000000, start_date=20220228T072343, end_date=20220228T072344
[2022-02-28 07:23:44,846] {standard_task_runner.py:92} ERROR - Failed to execute job 59 for task read_file_from_s3
Traceback (most recent call last):
  File "/home/airflow/.local/lib/python3.7/site-packages/airflow/task/task_runner/standard_task_runner.py", line 85, in _start_by_fork
    args.func(args, dag=self.dag)
  File "/home/airflow/.local/lib/python3.7/site-packages/airflow/cli/cli_parser.py", line 48, in command
    return func(*args, **kwargs)
  File "/home/airflow/.local/lib/python3.7/site-packages/airflow/utils/cli.py", line 92, in wrapper
    return f(*args, **kwargs)
  File "/home/airflow/.local/lib/python3.7/site-packages/airflow/cli/commands/task_command.py", line 298, in task_run
    _run_task_by_selected_method(args, dag, ti)
  File "/home/airflow/.local/lib/python3.7/site-packages/airflow/cli/commands/task_command.py", line 107, in _run_task_by_selected_method
    _run_raw_task(args, ti)
  File "/home/airflow/.local/lib/python3.7/site-packages/airflow/cli/commands/task_command.py", line 184, in _run_raw_task
    error_file=args.error_file,
  File "/home/airflow/.local/lib/python3.7/site-packages/airflow/utils/session.py", line 70, in wrapper
    return func(*args, session=session, **kwargs)
  File "/home/airflow/.local/lib/python3.7/site-packages/airflow/models/taskinstance.py", line 1334, in _run_raw_task
    self._execute_task_with_callbacks(context)
  File "/home/airflow/.local/lib/python3.7/site-packages/airflow/models/taskinstance.py", line 1460, in _execute_task_with_callbacks
    result = self._execute_task(context, self.task)
  File "/home/airflow/.local/lib/python3.7/site-packages/airflow/models/taskinstance.py", line 1516, in _execute_task
    result = execute_callable(context=context)
  File "/home/airflow/.local/lib/python3.7/site-packages/airflow/operators/python.py", line 174, in execute
    return_value = self.execute_callable()
  File "/home/airflow/.local/lib/python3.7/site-packages/airflow/operators/python.py", line 188, in execute_callable
    return self.python_callable(*self.op_args, **self.op_kwargs)
  File "/opt/airflow/dags/example_dag.py", line 17, in read_file_from_s3
    print(s3_hook.read_key(key, bucket_name))
  File "/home/airflow/.local/lib/python3.7/site-packages/airflow/providers/amazon/aws/hooks/s3.py", line 62, in wrapper
    return func(*bound_args.args, **bound_args.kwargs)
  File "/home/airflow/.local/lib/python3.7/site-packages/airflow/providers/amazon/aws/hooks/s3.py", line 90, in wrapper
    return func(*bound_args.args, **bound_args.kwargs)
  File "/home/airflow/.local/lib/python3.7/site-packages/airflow/providers/amazon/aws/hooks/s3.py", line 354, in read_key
    obj = self.get_key(key, bucket_name)
  File "/home/airflow/.local/lib/python3.7/site-packages/airflow/providers/amazon/aws/hooks/s3.py", line 62, in wrapper
    return func(*bound_args.args, **bound_args.kwargs)
  File "/home/airflow/.local/lib/python3.7/site-packages/airflow/providers/amazon/aws/hooks/s3.py", line 90, in wrapper
    return func(*bound_args.args, **bound_args.kwargs)
  File "/home/airflow/.local/lib/python3.7/site-packages/airflow/providers/amazon/aws/hooks/s3.py", line 340, in get_key
    obj.load()
  File "/home/airflow/.local/lib/python3.7/site-packages/boto3/resources/factory.py", line 505, in do_action
    response = action(self, *args, **kwargs)
  File "/home/airflow/.local/lib/python3.7/site-packages/boto3/resources/action.py", line 83, in __call__
    response = getattr(parent.meta.client, operation_name)(*args, **params)
  File "/home/airflow/.local/lib/python3.7/site-packages/botocore/client.py", line 391, in _api_call
    return self._make_api_call(operation_name, kwargs)
  File "/home/airflow/.local/lib/python3.7/site-packages/botocore/client.py", line 719, in _make_api_call
    raise error_class(parsed_response, operation_name)
botocore.exceptions.ClientError: An error occurred (404) when calling the HeadObject operation: Not Found
[2022-02-28 07:23:44,902] {local_task_job.py:154} INFO - Task exited with return code 1
[2022-02-28 07:23:44,953] {local_task_job.py:264} INFO - 0 downstream tasks scheduled from follow-on schedule check
