[2022-02-28 08:51:45,086] {taskinstance.py:1037} INFO - Dependencies all met for <TaskInstance: test_s3_connection.read_file_from_s3 scheduled__2022-02-25T00:00:00+00:00 [queued]>
[2022-02-28 08:51:45,113] {taskinstance.py:1037} INFO - Dependencies all met for <TaskInstance: test_s3_connection.read_file_from_s3 scheduled__2022-02-25T00:00:00+00:00 [queued]>
[2022-02-28 08:51:45,114] {taskinstance.py:1243} INFO - 
--------------------------------------------------------------------------------
[2022-02-28 08:51:45,115] {taskinstance.py:1244} INFO - Starting attempt 7 of 7
[2022-02-28 08:51:45,116] {taskinstance.py:1245} INFO - 
--------------------------------------------------------------------------------
[2022-02-28 08:51:45,135] {taskinstance.py:1264} INFO - Executing <Task(PythonOperator): read_file_from_s3> on 2022-02-25 00:00:00+00:00
[2022-02-28 08:51:45,143] {standard_task_runner.py:52} INFO - Started process 19989 to run task
[2022-02-28 08:51:45,157] {standard_task_runner.py:76} INFO - Running: ['***', 'tasks', 'run', 'test_s3_connection', 'read_file_from_s3', 'scheduled__2022-02-25T00:00:00+00:00', '--job-id', '74', '--raw', '--subdir', 'DAGS_FOLDER/example_dag.py', '--cfg-path', '/tmp/tmp79zbsho6', '--error-file', '/tmp/tmpyfxaglok']
[2022-02-28 08:51:45,164] {standard_task_runner.py:77} INFO - Job 74: Subtask read_file_from_s3
[2022-02-28 08:51:45,284] {logging_mixin.py:109} INFO - Running <TaskInstance: test_s3_connection.read_file_from_s3 scheduled__2022-02-25T00:00:00+00:00 [running]> on host cdd2ec182991
[2022-02-28 08:51:45,385] {taskinstance.py:1431} INFO - Exporting the following env vars:
AIRFLOW_CTX_DAG_OWNER=***
AIRFLOW_CTX_DAG_ID=test_s3_connection
AIRFLOW_CTX_TASK_ID=read_file_from_s3
AIRFLOW_CTX_EXECUTION_DATE=2022-02-25T00:00:00+00:00
AIRFLOW_CTX_DAG_RUN_ID=scheduled__2022-02-25T00:00:00+00:00
[2022-02-28 08:51:45,389] {taskinstance.py:1718} ERROR - Task failed with exception
Traceback (most recent call last):
  File "/home/airflow/.local/lib/python3.7/site-packages/airflow/models/taskinstance.py", line 1334, in _run_raw_task
    self._execute_task_with_callbacks(context)
  File "/home/airflow/.local/lib/python3.7/site-packages/airflow/models/taskinstance.py", line 1460, in _execute_task_with_callbacks
    result = self._execute_task(context, self.task)
  File "/home/airflow/.local/lib/python3.7/site-packages/airflow/models/taskinstance.py", line 1516, in _execute_task
    result = execute_callable(context=context)
  File "/home/airflow/.local/lib/python3.7/site-packages/airflow/operators/python.py", line 174, in execute
    return_value = self.execute_callable()
  File "/home/airflow/.local/lib/python3.7/site-packages/airflow/operators/python.py", line 188, in execute_callable
    return self.python_callable(*self.op_args, **self.op_kwargs)
  File "/opt/airflow/dags/example_dag.py", line 23, in read_file_from_s3
    s3_hook = airflow.hooks.S3_hook.S3Hook("my_airflow_conn_S3")
NameError: name '***' is not defined
[2022-02-28 08:51:45,426] {taskinstance.py:1282} INFO - Marking task as FAILED. dag_id=test_s3_connection, task_id=read_file_from_s3, execution_date=20220225T000000, start_date=20220228T085145, end_date=20220228T085145
[2022-02-28 08:51:45,453] {standard_task_runner.py:92} ERROR - Failed to execute job 74 for task read_file_from_s3
Traceback (most recent call last):
  File "/home/airflow/.local/lib/python3.7/site-packages/airflow/task/task_runner/standard_task_runner.py", line 85, in _start_by_fork
    args.func(args, dag=self.dag)
  File "/home/airflow/.local/lib/python3.7/site-packages/airflow/cli/cli_parser.py", line 48, in command
    return func(*args, **kwargs)
  File "/home/airflow/.local/lib/python3.7/site-packages/airflow/utils/cli.py", line 92, in wrapper
    return f(*args, **kwargs)
  File "/home/airflow/.local/lib/python3.7/site-packages/airflow/cli/commands/task_command.py", line 298, in task_run
    _run_task_by_selected_method(args, dag, ti)
  File "/home/airflow/.local/lib/python3.7/site-packages/airflow/cli/commands/task_command.py", line 107, in _run_task_by_selected_method
    _run_raw_task(args, ti)
  File "/home/airflow/.local/lib/python3.7/site-packages/airflow/cli/commands/task_command.py", line 184, in _run_raw_task
    error_file=args.error_file,
  File "/home/airflow/.local/lib/python3.7/site-packages/airflow/utils/session.py", line 70, in wrapper
    return func(*args, session=session, **kwargs)
  File "/home/airflow/.local/lib/python3.7/site-packages/airflow/models/taskinstance.py", line 1334, in _run_raw_task
    self._execute_task_with_callbacks(context)
  File "/home/airflow/.local/lib/python3.7/site-packages/airflow/models/taskinstance.py", line 1460, in _execute_task_with_callbacks
    result = self._execute_task(context, self.task)
  File "/home/airflow/.local/lib/python3.7/site-packages/airflow/models/taskinstance.py", line 1516, in _execute_task
    result = execute_callable(context=context)
  File "/home/airflow/.local/lib/python3.7/site-packages/airflow/operators/python.py", line 174, in execute
    return_value = self.execute_callable()
  File "/home/airflow/.local/lib/python3.7/site-packages/airflow/operators/python.py", line 188, in execute_callable
    return self.python_callable(*self.op_args, **self.op_kwargs)
  File "/opt/airflow/dags/example_dag.py", line 23, in read_file_from_s3
    s3_hook = airflow.hooks.S3_hook.S3Hook("my_airflow_conn_S3")
NameError: name '***' is not defined
[2022-02-28 08:51:45,488] {local_task_job.py:154} INFO - Task exited with return code 1
[2022-02-28 08:51:45,543] {local_task_job.py:264} INFO - 0 downstream tasks scheduled from follow-on schedule check
